Workbook

Sheet Training 1+Uji 1
A1: No | B1: Kepala Rumah Tangga | C1: Data | D1: Kelas Kesejahteraan | E1: IM 1 | F1: IM 2 | G1: IM 3 | H1: IM 4 | I1: IM 5 | J1: IM 6 | K1: IM 7 | L1: IM 8 | M1: IM 9 | N1: IM 10 | O1: IM 11 | P1: IM 12 | Q1: IM 13 | R1: IM 14 | S1: IM 15 | T1: IM 16 | U1: IM 17 | V1: IM 18 | W1: IM 19 | X1: IM 20 | Y1: IM 21 | Z1: IM 22 | AA1: IM 23 | AB1: IM 24 | AC1: IM 25 | AD1: IM 26 | AE1: IM 27 | AF1: IM 28 | AG1: IM 29 | AH1: IM 30 | AI1: IM 31 | AJ1: IM 32 | AK1: IM 33 | AL1: IM 34 | AM1: IM 35 | AN1: IM 36
A2: =ROW()-1 -> 1 | B2: Nanang Fathoni | C2: Training | D2: 1 | E2: C | F2: B | G2: A | H2: D | I2: D | J2: D | K2: C | L2: C | M2: B | N2: C | O2: A | P2: C | Q2: D | R2: B | S2: B | T2: D | U2: D | V2: D | W2: C | X2: A | Y2: B | Z2: A | AA2: A | AB2: A | AC2: A | AD2: A | AE2: A | AF2: A | AG2: B | AH2: A | AI2: A | AJ2: B | AK2: A | AL2: A | AM2: A | AN2: B
A3: =ROW()-1 -> 2 | B3: Muhaimin | C3: Training | D3: 1 | E3: D | F3: B | G3: C | H3: B | I3: D | J3: B | K3: D | L3: C | M3: C | N3: B | O3: B | P3: A | Q3: C | R3: B | S3: A | T3: D | U3: D | V3: D | W3: A | X3: A | Y3: A | Z3: D | AA3: B | AB3: A | AC3: A | AD3: A | AE3: A | AF3: A | AG3: A | AH3: B | AI3: A | AJ3: B | AK3: A | AL3: A | AM3: A | AN3: B
A4: =ROW()-1 -> 3 | B4: Sujiati | C4: Training | D4: 1 | E4: C | F4: B | G4: A | H4: D | I4: D | J4: D | K4: D | L4: C | M4: B | N4: B | O4: A | P4: B | Q4: D | R4: B | S4: B | T4: D | U4: D | V4: D | W4: C | X4: A | Y4: B | Z4: C | AA4: B | AB4: A | AC4: A | AD4: A | AE4: A | AF4: A | AG4: A | AH4: A | AI4: A | AJ4: A | AK4: A | AL4: A | AM4: B | AN4: B
A5: =ROW()-1 -> 4 | B5: Supriadi | C5: Training | D5: 1 | E5: D | F5: C | G5: C | H5: B | I5: D | J5: D | K5: D | L5: C | M5: B | N5: B | O5: A | P5: C | Q5: D | R5: B | S5: C | T5: D | U5: C | V5: C | W5: B | X5: A | Y5: B | Z5: B | AA5: B | AB5: A | AC5: A | AD5: A | AE5: A | AF5: A | AG5: A | AH5: B | AI5: A | AJ5: B | AK5: A | AL5: A | AM5: A | AN5: B
A6: =ROW()-1 -> 5 | B6: Lilik Rohma | C6: Training | D6: 1 | E6: C | F6: B | G6: B | H6: D | I6: D | J6: B | K6: C | L6: C | M6: C | N6: B | O6: A | P6: D | Q6: D | R6: B | S6: B | T6: D | U6: D | V6: D | W6: D | X6: A | Y6: B | Z6: C | AA6: B | AB6: A | AC6: A | AD6: A | AE6: A | AF6: A | AG6: B | AH6: B | AI6: A | AJ6: A | AK6: A | AL6: A | AM6: A | AN6: B
A7: =ROW()-1 -> 6 | B7: Supaiji Susanto | C7: Training | D7: 1 | E7: B | F7: B | G7: C | H7: D | I7: D | J7: B | K7: D | L7: C | M7: C | N7: C | O7: B | P7: B | Q7: D | R7: B | S7: B | T7: D | U7: D | V7: D | W7: D | X7: A | Y7: B | Z7: C | AA7: B | AB7: A | AC7: A | AD7: A | AE7: A | AF7: A | AG7: A | AH7: B | AI7: A | AJ7: B | AK7: A | AL7: A | AM7: A | AN7: B
A8: =ROW()-1 -> 7 | B8: Duparji | C8: Training | D8: 1 | E8: B | F8: B | G8: A | H8: B | I8: D | J8: D | K8: C | L8: C | M8: B | N8: B | O8: A | P8: D | Q8: D | R8: B | S8: C | T8: C | U8: C | V8: C | W8: D | X8: A | Y8: A | Z8: A | AA8: B | AB8: A | AC8: A | AD8: A | AE8: A | AF8: A | AG8: A | AH8: B | AI8: A | AJ8: B | AK8: A | AL8: A | AM8: B | AN8: B
A9: =ROW()-1 -> 8 | B9: Siti Juariyah | C9: Training | D9: 1 | E9: B | F9: D | G9: B | H9: D | I9: D | J9: D | K9: D | L9: C | M9: B | N9: B | O9: B | P9: A | Q9: D | R9: B | S9: A | T9: D | U9: D | V9: D | W9: B | X9: A | Y9: B | Z9: C | AA9: B | AB9: A | AC9: A | AD9: A | AE9: A | AF9: A | AG9: A | AH9: B | AI9: A | AJ9: B | AK9: A | AL9: A | AM9: A | AN9: B
A10: =ROW()-1 -> 9 | B10: Lilik Utami | C10: Training | D10: 1 | E10: B | F10: B | G10: C | H10: B | I10: D | J10: D | K10: D | L10: C | M10: C | N10: C | O10: B | P10: C | Q10: D | R10: B | S10: B | T10: D | U10: D | V10: D | W10: C | X10: A | Y10: B | Z10: A | AA10: B | AB10: A | AC10: A | AD10: A | AE10: A | AF10: A | AG10: A | AH10: B | AI10: A | AJ10: B | AK10: A | AL10: A | AM10: A | AN10: B
A11: =ROW()-1 -> 10 | B11: Sugito | C11: Training | D11: 1 | E11: B | F11: D | G11: C | H11: D | I11: D | J11: D | K11: D | L11: C | M11: B | N11: B | O11: C | P11: A | Q11: C | R11: B | S11: A | T11: C | U11: C | V11: C | W11: D | X11: A | Y11: A | Z11: C | AA11: B | AB11: A | AC11: A | AD11: A | AE11: A | AF11: A | AG11: A | AH11: B | AI11: A | AJ11: B | AK11: A | AL11: A | AM11: A | AN11: B
A12: =ROW()-1 -> 11 | B12: Sumbri | C12: Training | D12: 1 | E12: A | F12: C | G12: B | H12: B | I12: D | J12: D | K12: D | L12: C | M12: B | N12: B | O12: A | P12: C | Q12: D | R12: B | S12: B | T12: D | U12: D | V12: D | W12: A | X12: A | Y12: A | Z12: A | AA12: B | AB12: B | AC12: B | AD12: A | AE12: A | AF12: A | AG12: A | AH12: B | AI12: A | AJ12: B | AK12: A | AL12: A | AM12: A | AN12: B
A13: =ROW()-1 -> 12 | B13: Agung Irianto | C13: Training | D13: 1 | E13: D | F13: B | G13: A | H13: D | I13: D | J13: D | K13: D | L13: C | M13: C | N13: B | O13: B | P13: C | Q13: C | R13: B | S13: C | T13: D | U13: C | V13: D | W13: D | X13: A | Y13: A | Z13: C | AA13: B | AB13: B | AC13: B | AD13: A | AE13: A | AF13: A | AG13: A | AH13: B | AI13: A | AJ13: B | AK13: A | AL13: A | AM13: B | AN13: B
... A115: =ROW()-1 -> 114 | B115: Soim Qodari | C115: Uji | D115: 6 | E115: D | F115: D | G115: A | H115: D | I115: D | J115: D | K115: D | L115: C | M115: B | N115: A | O115: B | P115: D | Q115: D | R115: B | S115: D | T115: D | U115: B | V115: D | W115: B | X115: A | Y115: C | Z115: C | AA115: B | AB115: A | AC115: A | AD115: A | AE115: A | AF115: A | AG115: A | AH115: B | AI115: A | AJ115: B | AK115: B | AL115: A | AM115: B | AN115: B

Sheet Data Training 1
A1: No | B1: Kepala Rumah Tangga | C1: Kelas Kesejahteraan | D1: IM 1 | E1: IM 2 | F1: IM 3 | G1: IM 4 | H1: IM 5 | I1: IM 6 | J1: IM 7 | K1: IM 8 | L1: IM 9 | M1: IM 10 | N1: IM 11 | O1: IM 12 | P1: IM 13 | Q1: IM 14 | R1: IM 15 | S1: IM 16 | T1: IM 17 | U1: IM 18 | V1: IM 19 | W1: IM 20 | X1: IM 21 | Y1: IM 22 | Z1: IM 23 | AA1: IM 24 | AB1: IM 25 | AC1: IM 26 | AD1: IM 27 | AE1: IM 28 | AF1: IM 29 | AG1: IM 30 | AH1: IM 31 | AI1: IM 32 | AJ1: IM 33 | AK1: IM 34 | AL1: IM 35 | AM1: IM 36
A2: =ROW()-1 -> 1 | B2: Nanang Fathoni | C2: 1 | D2: C | E2: B | F2: A | G2: D | H2: D | I2: D | J2: C | K2: C | L2: B | M2: C | N2: A | O2: C | P2: D | Q2: B | R2: B | S2: D | T2: D | U2: D | V2: C | W2: A | X2: B | Y2: A | Z2: A | AA2: A | AB2: A | AC2: A | AD2: A | AE2: A | AF2: B | AG2: A | AH2: A | AI2: B | AJ2: A | AK2: A | AL2: A | AM2: B
A3: =ROW()-1 -> 2 | B3: Muhaimin | C3: 1 | D3: D | E3: B | F3: C | G3: B | H3: D | I3: B | J3: D | K3: C | L3: C | M3: B | N3: B | O3: A | P3: C | Q3: B | R3: A | S3: D | T3: D | U3: D | V3: A | W3: A | X3: A | Y3: D | Z3: B | AA3: A | AB3: A | AC3: A | AD3: A | AE3: A | AF3: A | AG3: B | AH3: A | AI3: B | AJ3: A | AK3: A | AL3: A | AM3: B
A4: =ROW()-1 -> 3 | B4: Sujiati | C4: 1 | D4: C | E4: B | F4: A | G4: D | H4: D | I4: D | J4: D | K4: C | L4: B | M4: B | N4: A | O4: B | P4: D | Q4: B | R4: B | S4: D | T4: D | U4: D | V4: C | W4: A | X4: B | Y4: C | Z4: B | AA4: A | AB4: A | AC4: A | AD4: A | AE4: A | AF4: A | AG4: A | AH4: A | AI4: A | AJ4: A | AK4: A | AL4: B | AM4: B | AR4: Rumus
A5: =ROW()-1 -> 4 | B5: Supriadi | C5: 1 | D5: D | E5: C | F5: C | G5: B | H5: D | I5: D | J5: D | K5: C | L5: B | M5: B | N5: A | O5: C | P5: D | Q5: B | R5: C | S5: D | T5: C | U5: C | V5: B | W5: A | X5: B | Y5: B | Z5: B | AA5: A | AB5: A | AC5: A | AD5: A | AE5: A | AF5: A | AG5: B | AH5: A | AI5: B | AJ5: A | AK5: A | AL5: A | AM5: B | AT5: Jumlah data latih (n) | AU5: Jumlah data uji (n)
A6: =ROW()-1 -> 5 | B6: Lilik Rohma | C6: 1 | D6: C | E6: B | F6: B | G6: D | H6: D | I6: B | J6: C | K6: C | L6: C | M6: B | N6: A | O6: D | P6: D | Q6: B | R6: B | S6: D | T6: D | U6: D | V6: D | W6: A | X6: B | Y6: C | Z6: B | AA6: A | AB6: A | AC6: A | AD6: A | AE6: A | AF6: B | AG6: B | AH6: A | AI6: A | AJ6: A | AK6: A | AL6: A | AM6: B | AT6: =COUNT(A2:A79) -> 78
A7: =ROW()-1 -> 6 | B7: Supaiji Susanto | C7: 1 | D7: B | E7: B | F7: C | G7: D | H7: D | I7: B | J7: D | K7: C | L7: C | M7: C | N7: B | O7: B | P7: D | Q7: B | R7: B | S7: D | T7: D | U7: D | V7: D | W7: A | X7: B | Y7: C | Z7: B | AA7: A | AB7: A | AC7: A | AD7: A | AE7: A | AF7: A | AG7: B | AH7: A | AI7: B | AJ7: A | AK7: A | AL7: A | AM7: B
A8: =ROW()-1 -> 7 | B8: Duparji | C8: 1 | D8: B | E8: B | F8: A | G8: B | H8: D | I8: D | J8: C | K8: C | L8: B | M8: B | N8: A | O8: D | P8: D | Q8: B | R8: C | S8: C | T8: C | U8: C | V8: D | W8: A | X8: A | Y8: A | Z8: B | AA8: A | AB8: A | AC8: A | AD8: A | AE8: A | AF8: A | AG8: B | AH8: A | AI8: B | AJ8: A | AK8: A | AL8: B | AM8: B | AT8: Kelas Kesejahteraan | AU8: KK1 | AV8: KK2 | AW8: KK3 | AX8: KK4 | AY8: KK5 | AZ8: KK6
A9: =ROW()-1 -> 8 | B9: Siti Juariyah | C9: 1 | D9: B | E9: D | F9: B | G9: D | H9: D | I9: D | J9: D | K9: C | L9: B | M9: B | N9: B | O9: A | P9: D | Q9: B | R9: A | S9: D | T9: D | U9: D | V9: B | W9: A | X9: B | Y9: C | Z9: B | AA9: A | AB9: A | AC9: A | AD9: A | AE9: A | AF9: A | AG9: B | AH9: A | AI9: B | AJ9: A | AK9: A | AL9: A | AM9: B | AR9: Keterangan | AU9: =COUNTIF(C:C,1) -> 13 | AV9: =COUNTIF(C:C,2) -> 13 | AW9: =COUNTIF(C:C,3) -> 13 | AX9: =COUNTIF(C:C,4) -> 13 | AY9: =COUNTIF(C:C,5) -> 13 | AZ9: =COUNTIF(C:C,6) -> 13
A10: =ROW()-1 -> 9 | B10: Lilik Utami | C10: 1 | D10: B | E10: B | F10: C | G10: B | H10: D | I10: D | J10: D | K10: C | L10: C | M10: C | N10: B | O10: C | P10: D | Q10: B | R10: B | S10: D | T10: D | U10: D | V10: C | W10: A | X10: B | Y10: A | Z10: B | AA10: A | AB10: A | AC10: A | AD10: A | AE10: A | AF10: A | AG10: B | AH10: A | AI10: B | AJ10: A | AK10: A | AL10: A | AM10: B | AR10: X: Data dengan class yang belum diketahui
A11: =ROW()-1 -> 10 | B11: Sugito | C11: 1 | D11: B | E11: D | F11: C | G11: D | H11: D | I11: D | J11: D | K11: C | L11: B | M11: B | N11: C | O11: A | P11: C | Q11: B | R11: A | S11: C | T11: C | U11: C | V11: D | W11: A | X11: A | Y11: C | Z11: B | AA11: A | AB11: A | AC11: A | AD11: A | AE11: A | AF11: A | AG11: B | AH11: A | AI11: B | AJ11: A | AK11: A | AL11: A | AM11: B | AR11: H: Hipotesis data yang merupakan suatu class spesifik
A12: =ROW()-1 -> 11 | B12: Sumbri | C12: 1 | D12: A | E12: C | F12: B | G12: B | H12: D | I12: D | J12: D | K12: C | L12: B | M12: B | N12: A | O12: C | P12: D | Q12: B | R12: B | S12: D | T12: D | U12: D | V12: A | W12: A | X12: A | Y12: A | Z12: B | AA12: B | AB12: B | AC12: A | AD12: A | AE12: A | AF12: A | AG12: B | AH12: A | AI12: B | AJ12: A | AK12: A | AL12: A | AM12: B | AR12: P(H|X) : Probabilitas data X terhadap kelas H (posterior probabilitas)
A13: =ROW()-1 -> 12 | B13: Agung Irianto | C13: 1 | D13: D | E13: B | F13: A | G13: D | H13: D | I13: D | J13: D | K13: C | L13: C | M13: B | N13: B | O13: C | P13: C | Q13: B | R13: C | S13: D | T13: C | U13: D | V13: D | W13: A | X13: A | Y13: C | Z13: B | AA13: B | AB13: B | AC13: A | AD13: A | AE13: A | AF13: A | AG13: B | AH13: A | AI13: B | AJ13: A | AK13: A | AL13: B | AM13: B | AR13: P(H) : Probabilitas awal dari kelas H (prior probabilitas)
A14: =ROW()-1 -> 13 | B14: Maftuqin | C14: 1 | D14: D | E14: D | F14: A | G14: D | H14: D | I14: D | J14: D | K14: C | L14: B | M14: A | N14: B | O14: B | P14: D | Q14: B | R14: B | S14: D | T14: B | U14: C | V14: D | W14: A | X14: B | Y14: C | Z14: B | AA14: B | AB14: B | AC14: A | AD14: A | AE14: A | AF14: A | AG14: B | AH14: A | AI14: B | AJ14: B | AK14: A | AL14: A | AM14: B | AR14: P(X|H) : Probabilitas munculnya data X pada kelas H (likelihood)
A15: =ROW()-1 -> 14 | B15: Sigit Pramono | C15: 2 | D15: A | E15: D | F15: B | G15: B | H15: D | I15: D | J15: D | K15: C | L15: C | M15: B | N15: A | O15: C | P15: D | Q15: B | R15: A | S15: D | T15: D | U15: D | V15: A | W15: A | X15: A | Y15: A | Z15: B | AA15: A | AB15: A | AC15: A | AD15: A | AE15: A | AF15: A | AG15: B | AH15: A | AI15: A | AJ15: A | AK15: A | AL15: B | AM15: B | AR15: P(X) : Probabilitas kemunculan data X (evidence)
A16: =ROW()-1 -> 15 | B16: Choiri Zain | C16: 2 | D16: D | E16: B | F16: A | G16: B | H16: D | I16: D | J16: B | K16: A | L16: B | M16: B | N16: A | O16: A | P16: D | Q16: B | R16: A | S16: D | T16: D | U16: D | V16: A | W16: A | X16: A | Y16: A | Z16: B | AA16: A | AB16: A | AC16: A | AD16: A | AE16: A | AF16: A | AG16: B | AH16: A | AI16: B | AJ16: A | AK16: A | AL16: A | AM16: B
A17: =ROW()-1 -> 16 | B17: Musana | C17: 2 | D17: D | E17: D | F17: C | G17: C | H17: D | I17: D | J17: C | K17: C | L17: C | M17: A | N17: A | O17: A | P17: D | Q17: A | R17: D | S17: D | T17: D | U17: D | V17: D | W17: A | X17: B | Y17: C | Z17: B | AA17: A | AB17: A | AC17: A | AD17: A | AE17: A | AF17: A | AG17: A | AH17: A | AI17: B | AJ17: A | AK17: A | AL17: A | AM17: A
A18: =ROW()-1 -> 17 | B18: Edy Askandar | C18: 2 | D18: D | E18: D | F18: B | G18: D | H18: D | I18: D | J18: D | K18: C | L18: C | M18: A | N18: A | O18: C | P18: D | Q18: A | R18: C | S18: D | T18: B | U18: A | V18: D | W18: C | X18: A | Y18: A | Z18: B | AA18: A | AB18: A | AC18: A | AD18: A | AE18: A | AF18: A | AG18: B | AH18: A | AI18: B | AJ18: A | AK18: A | AL18: A | AM18: B
A19: =ROW()-1 -> 18 | B19: Aslicha | C19: 2 | D19: C | E19: D | F19: A | G19: D | H19: D | I19: D | J19: C | K19: C | L19: B | M19: A | N19: A | O19: D | P19: D | Q19: A | R19: D | S19: D | T19: C | U19: D | V19: D | W19: A | X19: A | Y19: A | Z19: B | AA19: A | AB19: A | AC19: A | AD19: A | AE19: A | AF19: A | AG19: B | AH19: A | AI19: B | AJ19: A | AK19: A | AL19: A | AM19: B
A20: =ROW()-1 -> 19 | B20: Mardia Ningsih | C20: 2 | D20: D | E20: D | F20: B | G20: D | H20: D | I20: D | J20: C | K20: C | L20: B | M20: C | N20: C | O20: B | P20: D | Q20: B | R20: A | S20: D | T20: D | U20: D | V20: D | W20: A | X20: A | Y20: C | Z20: B | AA20: A | AB20: A | AC20: A | AD20: A | AE20: A | AF20: A | AG20: B | AH20: A | AI20: A | AJ20: A | AK20: A | AL20: B | AM20: A
A21: =ROW()-1 -> 20 | B21: Palilo | C21: 2 | D21: A | E21: D | F21: C | G21: D | H21: D | I21: D | J21: D | K21: C | L21: B | M21: C | N21: B | O21: D | P21: D | Q21: B | R21: B | S21: D | T21: D | U21: D | V21: D | W21: A | X21: B | Y21: C | Z21: B | AA21: A | AB21: A | AC21: A | AD21: A | AE21: A | AF21: A | AG21: B | AH21: A | AI21: B | AJ21: A | AK21: A | AL21: B | AM21: B | AR21: 1. Menentukan probabilitas kelas P(H) / Prior probability
A22: =ROW()-1 -> 21 | B22: Harmanto | C22: 2 | D22: B | E22: D | F22: B | G22: D | H22: D | I22: D | J22: C | K22: C | L22: C | M22: C | N22: C | O22: C | P22: D | Q22: B | R22: B | S22: D | T22: D | U22: D | V22: D | W22: A | X22: A | Y22: A | Z22: B | AA22: A | AB22: A | AC22: A | AD22: A | AE22: A | AF22: A | AG22: B | AH22: A | AI22: B | AJ22: A | AK22: A | AL22: A | AM22: B | AS22: Kelas Kesejahteraan 1 | AT22: Sangat miskin | AU22: 13 | AV22: /78 | AW22: =AU9/AT6 -> 0.16666667
A23: =ROW()-1 -> 22 | B23: Masprio | C23: 2 | D23: D | E23: B | F23: C | G23: C | H23: D | I23: D | J23: D | K23: C | L23: C | M23: C | N23: B | O23: C | P23: D | Q23: B | R23: C | S23: D | T23: C | U23: C | V23: C | W23: A | X23: A | Y23: A | Z23: B | AA23: A | AB23: A | AC23: A | AD23: A | AE23: A | AF23: A | AG23: B | AH23: A | AI23: B | AJ23: A | AK23: A | AL23: B | AM23: B | AS23: Kelas Kesejahteraan 2 | AT23: Miskin | AU23: 13 | AV23: /78 | AW23: =AV9/AT6 -> 0.16666667
A24: =ROW()-1 -> 23 | B24: Susito | C24: 2 | D24: A | E24: D | F24: B | G24: D | H24: D | I24: D | J24: D | K24: C | L24: B | M24: C | N24: B | O24: C | P24: D | Q24: B | R24: B | S24: D | T24: D | U24: D | V24: B | W24: A | X24: A | Y24: C | Z24: B | AA24: A | AB24: A | AC24: A | AD24: A | AE24: A | AF24: A | AG24: B | AH24: A | AI24: A | AJ24: A | AK24: A | AL24: A | AM24: B | AS24: Kelas Kesejahteraan 3 | AT24: Hampir Miskin | AU24: 13 | AV24: /78 | AW24: =AW9/AT6 -> 0.16666667
A25: =ROW()-1 -> 24 | B25: Achmad Toha | C25: 2 | D25: D | E25: D | F25: C | G25: C | H25: D | I25: B | J25: C | K25: C | L25: B | M25: B | N25: A | O25: D | P25: D | Q25: A | R25: D | S25: D | T25: C | U25: D | V25: D | W25: B | X25: A | Y25: C | Z25: B | AA25: B | AB25: A | AC25: A | AD25: A | AE25: A | AF25: A | AG25: B | AH25: A | AI25: B | AJ25: A | AK25: A | AL25: B | AM25: B | AS25: Kelas Kesejahteraan 4 | AT25: Rentan Miskin | AU25: 13 | AV25: /78 | AW25: =AX9/AT6 -> 0.16666667
A26: =ROW()-1 -> 25 | B26: Jumani | C26: 2 | D26: D | E26: B | F26: D | G26: D | H26: D | I26: D | J26: D | K26: C | L26: B | M26: B | N26: B | O26: D | P26: D | Q26: B | R26: D | S26: D | T26: D | U26: D | V26: D | W26: B | X26: A | Y26: A | Z26: B | AA26: B | AB26: B | AC26: A | AD26: A | AE26: A | AF26: A | AG26: B | AH26: A | AI26: A | AJ26: B | AK26: A | AL26: A | AM26: B | AS26: Kelas Kesejahteraan 5 | AT26: Pas-Pasan | AU26: 13 | AV26: /78 | AW26: =AY9/AT6 -> 0.16666667
A27: =ROW()-1 -> 26 | B27: Hariyadi | C27: 2 | D27: B | E27: B | F27: B | G27: C | H27: D | I27: D | J27: C | K27: C | L27: C | M27: A | N27: A | O27: A | P27: D | Q27: A | R27: D | S27: D | T27: D | U27: D | V27: A | W27: A | X27: B | Y27: C | Z27: B | AA27: A | AB27: A | AC27: A | AD27: A | AE27: A | AF27: A | AG27: A | AH27: A | AI27: B | AJ27: A | AK27: A | AL27: A | AM27: B | AS27: Kelas Kesejahteraan 6 | AT27: Menengah Keatas | AU27: 13 | AV27: /78 | AW27: =AZ9/AT6 -> 0.16666667
A28: =ROW()-1 -> 27 | B28: Suwari | C28: 3 | D28: D | E28: B | F28: B | G28: D | H28: D | I28: D | J28: C | K28: C | L28: B | M28: B | N28: A | O28: D | P28: C | Q28: B | R28: C | S28: D | T28: D | U28: D | V28: D | W28: A | X28: B | Y28: B | Z28: B | AA28: A | AB28: A | AC28: A | AD28: A | AE28: A | AF28: A | AG28: B | AH28: A | AI28: B | AJ28: A | AK28: A | AL28: A | AM28: B
A29: =ROW()-1 -> 28 | B29: Suratmi | C29: 3 | D29: D | E29: A | F29: A | G29: B | H29: D | I29: D | J29: D | K29: C | L29: C | M29: B | N29: A | O29: C | P29: C | Q29: C | R29: D | S29: D | T29: B | U29: B | V29: C | W29: A | X29: D | Y29: B | Z29: B | AA29: B | AB29: B | AC29: A | AD29: A | AE29: A | AF29: A | AG29: B | AH29: A | AI29: A | AJ29: A | AK29: A | AL29: A | AM29: B | AR29: 2. Menentukan probabilitas atribut setiap kelasnya (P(X|H)) / Likelihood
A30: =ROW()-1 -> 29 | B30: Komsatun | C30: 3 | D30: D | E30: D | F30: A | G30: D | H30: D | I30: C | J30: D | K30: C | L30: B | M30: A | N30: A | O30: C | P30: D | Q30: D | R30: D | S30: D | T30: D | U30: D | V30: A | W30: A | X30: A | Y30: D | Z30: B | AA30: A | AB30: A | AC30: A | AD30: A | AE30: A | AF30: A | AG30: B | AH30: A | AI30: B | AJ30: A | AK30: A | AL30: A | AM30: B | AS30: P(IM 1 | Kelas Kesejahteraan) | AT30: 1 | AU30: 2 | AV30: 3 | AW30: 4 | AX30: 5 | AY30: 6
A31: =ROW()-1 -> 30 | B31: Sri Astuti | C31: 3 | D31: C | E31: B | F31: B | G31: C | H31: D | I31: C | J31: D | K31: C | L31: B | M31: A | N31: A | O31: D | P31: D | Q31: A | R31: D | S31: D | T31: D | U31: D | V31: D | W31: A | X31: A | Y31: A | Z31: A | AA31: A | AB31: A | AC31: A | AD31: A | AE31: A | AF31: A | AG31: A | AH31: A | AI31: B | AJ31: A | AK31: A | AL31: B | AM31: A | AS31: P(IM 1 A | Kelas Kesejahteraan) | AT31: =COUNTIFS(D:D,"A",C:C,1)/COUNTIF(C:C,1) -> 0.076923077 | AU31: =COUNTIFS(D:D,"A",C:C,2)/COUNTIF(C:C,2) -> 0.23076923 | AV31: =COUNTIFS(D:D,"A",C:C,3)/COUNTIF(C:C,3) -> 0.076923077 | AW31: =COUNTIFS(D:D,"A",C:C,4)/COUNTIF(C:C,4) -> 0 | AX31: =COUNTIFS(D:D,"A",C:C,5)/COUNTIF(C:C,5) -> 0.076923077 | AY31: =COUNTIFS(D:D,"A",C:C,6)/COUNTIF(C:C,6) -> 0.076923077
A32: =ROW()-1 -> 31 | B32: Suis | C32: 3 | D32: C | E32: D | F32: B | G32: D | H32: D | I32: D | J32: D | K32: C | L32: C | M32: B | N32: A | O32: C | P32: D | Q32: B | R32: B | S32: D | T32: D | U32: D | V32: D | W32: A | X32: C | Y32: C | Z32: B | AA32: A | AB32: A | AC32: A | AD32: A | AE32: A | AF32: A | AG32: B | AH32: A | AI32: B | AJ32: A | AK32: A | AL32: A | AM32: B | AS32: P(IM 1 B | Kelas Kesejahteraan) | AT32: =COUNTIFS(D:D,"B",C:C,1)/COUNTIF(C:C,1) -> 0.38461538 | AU32: =COUNTIFS(D:D,"B",C:C,2)/COUNTIF(C:C,2) -> 0.15384615 | AV32: =COUNTIFS(D:D,"B",C:C,3)/COUNTIF(C:C,3) -> 0 | AW32: =COUNTIFS(D:D,"B",C:C,4)/COUNTIF(C:C,4) -> 0.23076923 | AX32: =COUNTIFS(D:D,"B",C:C,5)/COUNTIF(C:C,5) -> 0 | AY32: =COUNTIFS(D:D,"B",C:C,6)/COUNTIF(C:C,6) -> 0
A33: =ROW()-1 -> 32 | B33: Muhammad Harun | C33: 3 | D33: A | E33: D | F33: B | G33: D | H33: D | I33: D | J33: D | K33: C | L33: B | M33: C | N33: C | O33: D | P33: B | Q33: B | R33: C | S33: D | T33: C | U33: C | V33: D | W33: A | X33: B | Y33: C | Z33: B | AA33: A | AB33: A | AC33: A | AD33: A | AE33: A | AF33: A | AG33: B | AH33: A | AI33: B | AJ33: A | AK33: A | AL33: B | AM33: B | AS33: P(IM 1 C | Kelas Kesejahteraan) | AT33: =COUNTIFS(D:D,"C",C:C,1)/COUNTIF(C:C,1) -> 0.23076923 | AU33: =COUNTIFS(D:D,"C",C:C,2)/COUNTIF(C:C,2) -> 0.076923077 | AV33: =COUNTIFS(D:D,"C",C:C,3)/COUNTIF(C:C,3) -> 0.30769231 | AW33: =COUNTIFS(D:D,"C",C:C,4)/COUNTIF(C:C,4) -> 0.076923077 | AX33: =COUNTIFS(D:D,"C",C:C,5)/COUNTIF(C:C,5) -> 0.15384615 | AY33: =COUNTIFS(D:D,"C",C:C,6)/COUNTIF(C:C,6) -> 0
A34: =ROW()-1 -> 33 | B34: Nurul Wahyuni | C34: 3 | D34: C | E34: D | F34: B | G34: D | H34: D | I34: D | J34: D | K34: C | L34: C | M34: C | N34: B | O34: D | P34: D | Q34: B | R34: C | S34: C | T34: D | U34: D | V34: C | W34: A | X34: C | Y34: C | Z34: B | AA34: A | AB34: A | AC34: A | AD34: A | AE34: A | AF34: A | AG34: B | AH34: A | AI34: B | AJ34: A | AK34: A | AL34: A | AM34: B | AS34: P(IM 1 D | Kelas Kesejahteraan) | AT34: =COUNTIFS(D:D,"D",C:C,1)/COUNTIF(C:C,1) -> 0.30769231 | AU34: =COUNTIFS(D:D,"D",C:C,2)/COUNTIF(C:C,2) -> 0.53846154 | AV34: =COUNTIFS(D:D,"D",C:C,3)/COUNTIF(C:C,3) -> 0.61538462 | AW34: =COUNTIFS(D:D,"D",C:C,4)/COUNTIF(C:C,4) -> 0.69230769 | AX34: =COUNTIFS(D:D,"D",C:C,5)/COUNTIF(C:C,5) -> 0.76923077 | AY34: =COUNTIFS(D:D,"D",C:C,6)/COUNTIF(C:C,6) -> 0.92307692
A35: =ROW()-1 -> 34 | B35: Maulana Supri | C35: 3 | D35: D | E35: B | F35: B | G35: D | H35: D | I35: D | J35: D | K35: C | L35: C | M35: B | N35: B | O35: C | P35: D | Q35: B | R35: B | S35: C | T35: D | U35: D | V35: D | W35: A | X35: B | Y35: C | Z35: B | AA35: A | AB35: A | AC35: A | AD35: A | AE35: A | AF35: A | AG35: B | AH35: A | AI35: A | AJ35: A | AK35: A | AL35: B | AM35: B
A36: =ROW()-1 -> 35 | B36: Dadik Siji | C36: 3 | D36: D | E36: B | F36: B | G36: C | H36: D | I36: D | J36: D | K36: C | L36: B | M36: B | N36: B | O36: C | P36: D | Q36: B | R36: B | S36: D | T36: D | U36: D | V36: D | W36: A | X36: B | Y36: C | Z36: B | AA36: A | AB36: A | AC36: A | AD36: A | AE36: A | AF36: A | AG36: B | AH36: A | AI36: B | AJ36: A | AK36: A | AL36: B | AM36: B | AS36: P(IM 2 | Kelas Kesejahteraan) | AT36: 1 | AU36: 2 | AV36: 3 | AW36: 4 | AX36: 5 | AY36: 6
A37: =ROW()-1 -> 36 | B37: Ali Hari Wahyu | C37: 3 | D37: D | E37: B | F37: B | G37: D | H37: D | I37: D | J37: C | K37: C | L37: B | M37: A | N37: A | O37: D | P37: C | Q37: B | R37: C | S37: D | T37: D | U37: D | V37: D | W37: A | X37: B | Y37: B | Z37: B | AA37: A | AB37: A | AC37: A | AD37: A | AE37: A | AF37: A | AG37: B | AH37: A | AI37: A | AJ37: A | AK37: A | AL37: A | AM37: B | AS37: P(IM 2 A | Kelas Kesejahteraan) | AT37: =COUNTIFS(E:E,"A",C:C,1)/COUNTIF(C:C,1) -> 0 | AU37: =COUNTIFS(E:E,"A",C:C,2)/COUNTIF(C:C,2) -> 0 | AV37: =COUNTIFS(E:E,"A",C:C,3)/COUNTIF(C:C,3) -> 0.076923077 | AW37: =COUNTIFS(E:E,"A",C:C,4)/COUNTIF(C:C,4) -> 0 | AX37: =COUNTIFS(E:E,"A",C:C,5)/COUNTIF(C:C,5) -> 0 | AY37: =COUNTIFS(E:E,"A",C:C,6)/COUNTIF(C:C,6) -> 0
A38: =ROW()-1 -> 37 | B38: Abdul Salam | C38: 3 | D38: D | E38: D | F38: D | G38: D | H38: D | I38: D | J38: D | K38: C | L38: C | M38: C | N38: D | O38: C | P38: C | Q38: C | R38: C | S38: D | T38: D | U38: D | V38: D | W38: B | X38: A | Y38: A | Z38: B | AA38: A | AB38: B | AC38: A | AD38: A | AE38: A | AF38: A | AG38: A | AH38: A | AI38: B | AJ38: A | AK38: A | AL38: A | AM38: B | AS38: P(IM 2 B | Kelas Kesejahteraan) | AT38: =COUNTIFS(E:E,"B",C:C,1)/COUNTIF(C:C,1) -> 0.61538462 | AU38: =COUNTIFS(E:E,"B",C:C,2)/COUNTIF(C:C,2) -> 0.30769231 | AV38: =COUNTIFS(E:E,"B",C:C,3)/COUNTIF(C:C,3) -> 0.46153846 | AW38: =COUNTIFS(E:E,"B",C:C,4)/COUNTIF(C:C,4) -> 0.69230769 | AX38: =COUNTIFS(E:E,"B",C:C,5)/COUNTIF(C:C,5) -> 0.46153846 | AY38: =COUNTIFS(E:E,"B",C:C,6)/COUNTIF(C:C,6) -> 0.38461538
A39: =ROW()-1 -> 38 | B39: Lisruchisi | C39: 3 | D39: D | E39: B | F39: B | G39: D | H39: D | I39: D | J39: D | K39: C | L39: B | M39: B | N39: A | O39: D | P39: C | Q39: B | R39: D | S39: D | T39: D | U39: D | V39: A | W39: A | X39: A | Y39: C | Z39: B | AA39: A | AB39: A | AC39: A | AD39: A | AE39: A | AF39: A | AG39: B | AH39: A | AI39: B | AJ39: A | AK39: A | AL39: A | AM39: A | AS39: P(IM 2 C | Kelas Kesejahteraan) | AT39: =COUNTIFS(E:E,"C",C:C,1)/COUNTIF(C:C,1) -> 0.15384615 | AU39: =COUNTIFS(E:E,"C",C:C,2)/COUNTIF(C:C,2) -> 0 | AV39: =COUNTIFS(E:E,"C",C:C,3)/COUNTIF(C:C,3) -> 0 | AW39: =COUNTIFS(E:E,"C",C:C,4)/COUNTIF(C:C,4) -> 0 | AX39: =COUNTIFS(E:E,"C",C:C,5)/COUNTIF(C:C,5) -> 0 | AY39: =COUNTIFS(E:E,"C",C:C,6)/COUNTIF(C:C,6) -> 0
A40: =ROW()-1 -> 39 | B40: Titin | C40: 3 | D40: C | E40: D | F40: B | G40: C | H40: D | I40: D | J40: D | K40: C | L40: B | M40: A | N40: A | O40: D | P40: D | Q40: A | R40: D | S40: D | T40: D | U40: D | V40: D | W40: A | X40: A | Y40: A | Z40: A | AA40: A | AB40: A | AC40: A | AD40: A | AE40: A | AF40: A | AG40: A | AH40: A | AI40: B | AJ40: A | AK40: A | AL40: B | AM40: A | AS40: P(IM 2 D | Kelas Kesejahteraan) | AT40: =COUNTIFS(E:E,"D",C:C,1)/COUNTIF(C:C,1) -> 0.23076923 | AU40: =COUNTIFS(E:E,"D",C:C,2)/COUNTIF(C:C,2) -> 0.69230769 | AV40: =COUNTIFS(E:E,"D",C:C,3)/COUNTIF(C:C,3) -> 0.46153846 | AW40: =COUNTIFS(E:E,"D",C:C,4)/COUNTIF(C:C,4) -> 0.30769231 | AX40: =COUNTIFS(E:E,"D",C:C,5)/COUNTIF(C:C,5) -> 0.53846154 | AY40: =COUNTIFS(E:E,"D",C:C,6)/COUNTIF(C:C,6) -> 0.61538462
...

Sheet Data Uji 1
A1: No | B1: Kepala Rumah Tangga | C1: Kelas Kesejahteraan | D1: IM 1 | E1: IM 2 | F1: IM 3 | G1: IM 4 | H1: IM 5 | I1: IM 6 | J1: IM 7 | K1: IM 8 | L1: IM 9 | M1: IM 10 | N1: IM 11 | O1: IM 12 | P1: IM 13 | Q1: IM 14 | R1: IM 15 | S1: IM 16 | T1: IM 17 | U1: IM 18 | V1: IM 19 | W1: IM 20 | X1: IM 21 | Y1: IM 22 | Z1: IM 23 | AA1: IM 24 | AB1: IM 25 | AC1: IM 26 | AD1: IM 27 | AE1: IM 28 | AF1: IM 29 | AG1: IM 30 | AH1: IM 31 | AI1: IM 32 | AJ1: IM 33 | AK1: IM 34 | AL1: IM 35 | AM1: IM 36 | AO1: Menguji data uji dengan menggunakan model yang telah di training sebelumnya
A2: =ROW()-1 -> 1 | B2: Nur Sakinah | C2: 1 | D2: A | E2: D | F2: B | G2: D | H2: D | I2: D | J2: C | K2: C | L2: C | M2: C | N2: B | O2: D | P2: D | Q2: B | R2: B | S2: D | T2: D | U2: D | V2: C | W2: A | X2: A | Y2: C | Z2: A | AA2: A | AB2: A | AC2: A | AD2: A | AE2: A | AF2: A | AG2: B | AH2: A | AI2: B | AJ2: A | AK2: A | AL2: A | AM2: B | AN2: 1 | AO2: Nur sakinah | AQ2: Kelas Kesejahteraan | AR2: IM 1 | AS2: IM 2 | AT2: IM 3 | AU2: IM 4 | AV2: IM 5 | AW2: IM 6 | AX2: IM 7 | AY2: IM 8 | AZ2: IM 9 | BA2: IM 10 | BB2: IM 11 | BC2: IM 12 | BD2: IM 13 | BE2: IM 14 | BF2: IM 15 | BG2: IM 16 | BH2: IM 17 | BI2: IM 18 | BJ2: IM 19 | BK2: IM 20 | BL2: IM 21 | BM2: IM 22 | BN2: IM 23 | BO2: IM 24 | BP2: IM 25 | BQ2: IM 26 | BR2: IM 27 | BS2: IM 28 | BT2: IM 29 | BU2: IM 30 | BV2: IM 31 | BW2: IM 32 | BX2: IM 33 | BY2: IM 34 | BZ2: IM 35 | CA2: IM 36
A3: =ROW()-1 -> 2 | B3: Juariyah | C3: 1 | D3: C | E3: B | F3: A | G3: D | H3: D | I3: D | J3: D | K3: C | L3: B | M3: B | N3: A | O3: B | P3: D | Q3: B | R3: B | S3: D | T3: D | U3: D | V3: C | W3: A | X3: B | Y3: C | Z3: B | AA3: A | AB3: A | AC3: A | AD3: A | AE3: A | AF3: A | AG3: A | AH3: A | AI3: A | AJ3: A | AK3: A | AL3: B | AM3: B | AQ3: 1 | AR3: A | AS3: D | AT3: B | AU3: D | AV3: D | AW3: D | AX3: C | AY3: C | AZ3: C | BA3: C | BB3: B | BC3: D | BD3: D | BE3: B | BF3: B | BG3: D | BH3: D | BI3: D | BJ3: C | BK3: A | BL3: A | BM3: C | BN3: A | BO3: A | BP3: A | BQ3: A | BR3: A | BS3: A | BT3: A | BU3: B | BV3: A | BW3: B | BX3: A | BY3: A | BZ3: A | CA3: B
A4: =ROW()-1 -> 3 | B4: Khoirun Sasmito | C4: 1 | D4: C | E4: D | F4: B | G4: D | H4: D | I4: B | J4: C | K4: C | L4: C | M4: B | N4: A | O4: D | P4: D | Q4: B | R4: B | S4: D | T4: D | U4: D | V4: D | W4: A | X4: B | Y4: C | Z4: B | AA4: A | AB4: A | AC4: A | AD4: A | AE4: A | AF4: B | AG4: B | AH4: A | AI4: A | AJ4: A | AK4: A | AL4: A | AM4: B | AO4: P(Kesejahteraan|1) = | AQ4: ='Data Training 1'!AW22*'Data Training 1'!AT31*'Data Training 1'!AT40*'Data Training 1'!AT44*'Data Training 1'!AT52*'Data Training 1'!AT58*'Data Training 1'!AT64*'Data Training 1'!AT69*'Data Training 1'!AT75*'Data Training 1'!AT81*'Data Training 1'!AT87*'Data Training 1'!AT92*'Data Training 1'!AT100*'Data Training 1'!AT106*'Data Training 1'!AT110*'Data Training 1'!AT116*'Data Training 1'!AT124*'Data Training 1'!AT130*'Data Training 1'!AT136*'Data Training 1'!AT141*'Data Training 1'!AT145*'Data Training 1'!AT151*'Data Training 1'!AT159*'Data Training 1'!AT163*'Data Training 1'!AT167*'Data Training 1'!AT171*'Data Training 1'!AT175*'Data Training 1'!AT179*'Data Training 1'!AT183*'Data Training 1'!AT187*'Data Training 1'!AT192*'Data Training 1'!AT195*'Data Training 1'!AT200*'Data Training 1'!AT203*'Data Training 1'!AT207*'Data Training 1'!AT211*'Data Training 1'!AT216 -> 6.5677962e-11
A5: =ROW()-1 -> 4 | B5: Abd. Rochim | C5: 1 | D5: D | E5: B | F5: C | G5: B | H5: D | I5: D | J5: D | K5: C | L5: C | M5: C | N5: C | O5: D | P5: D | Q5: B | R5: B | S5: D | T5: D | U5: D | V5: D | W5: A | X5: A | Y5: A | Z5: B | AA5: B | AB5: B | AC5: A | AD5: A | AE5: A | AF5: A | AG5: B | AH5: A | AI5: B | AJ5: B | AK5: A | AL5: A | AM5: B | AO5: P(Kesejahteraan|2) = | AQ5: ='Data Training 1'!AW23*'Data Training 1'!AU31*'Data Training 1'!AU40*'Data Training 1'!AU44*'Data Training 1'!AU52*'Data Training 1'!AU58*'Data Training 1'!AU64*'Data Training 1'!AU69*'Data Training 1'!AU75*'Data Training 1'!AU81*'Data Training 1'!AU87*'Data Training 1'!AU92*'Data Training 1'!AU100*'Data Training 1'!AU106*'Data Training 1'!AU110*'Data Training 1'!AU116*'Data Training 1'!AU124*'Data Training 1'!AU130*'Data Training 1'!AU136*'Data Training 1'!AU141*'Data Training 1'!AU145*'Data Training 1'!AU151*'Data Training 1'!AU159*'Data Training 1'!AU163*'Data Training 1'!AU167*'Data Training 1'!AU171*'Data Training 1'!AU175*'Data Training 1'!AU179*'Data Training 1'!AU183*'Data Training 1'!AU187*'Data Training 1'!AU192*'Data Training 1'!AU195*'Data Training 1'!AU200*'Data Training 1'!AU203*'Data Training 1'!AU207*'Data Training 1'!AU211*'Data Training 1'!AU216 -> 0
A6: =ROW()-1 -> 5 | B6: Sumirah | C6: 1 | D6: D | E6: B | F6: A | G6: B | H6: D | I6: D | J6: D | K6: C | L6: B | M6: B | N6: C | O6: A | P6: D | Q6: B | R6: C | S6: D | T6: D | U6: D | V6: D | W6: A | X6: A | Y6: A | Z6: B | AA6: B | AB6: B | AC6: A | AD6: A | AE6: A | AF6: A | AG6: A | AH6: A | AI6: A | AJ6: A | AK6: A | AL6: A | AM6: B | AO6: P(Kesejahteraan|3) = | AQ6: ='Data Training 1'!AW24*'Data Training 1'!AV31*'Data Training 1'!AV40*'Data Training 1'!AV44*'Data Training 1'!AV52*'Data Training 1'!AV58*'Data Training 1'!AV64*'Data Training 1'!AV69*'Data Training 1'!AV75*'Data Training 1'!AV81*'Data Training 1'!AV87*'Data Training 1'!AV92*'Data Training 1'!AV100*'Data Training 1'!AV106*'Data Training 1'!AV110*'Data Training 1'!AV116*'Data Training 1'!AV124*'Data Training 1'!AV130*'Data Training 1'!AV136*'Data Training 1'!AV141*'Data Training 1'!AV145*'Data Training 1'!AV151*'Data Training 1'!AV159*'Data Training 1'!AV163*'Data Training 1'!AV167*'Data Training 1'!AV171*'Data Training 1'!AV175*'Data Training 1'!AV179*'Data Training 1'!AV183*'Data Training 1'!AV187*'Data Training 1'!AV192*'Data Training 1'!AV195*'Data Training 1'!AV200*'Data Training 1'!AV203*'Data Training 1'!AV207*'Data Training 1'!AV211*'Data Training 1'!AV216 -> 1.7783571e-10
A7: =ROW()-1 -> 6 | B7: Titik Suharnik | C7: 1 | D7: D | E7: B | F7: C | G7: B | H7: D | I7: D | J7: D | K7: C | L7: B | M7: B | N7: C | O7: D | P7: D | Q7: B | R7: C | S7: D | T7: D | U7: D | V7: A | W7: A | X7: A | Y7: A | Z7: B | AA7: B | AB7: B | AC7: A | AD7: A | AE7: A | AF7: A | AG7: B | AH7: A | AI7: B | AJ7: A | AK7: A | AL7: B | AM7: B | AO7: P(Kesejahteraan|4) = | AQ7: ='Data Training 1'!AW25*'Data Training 1'!AW31*'Data Training 1'!AW40*'Data Training 1'!AW44*'Data Training 1'!AW52*'Data Training 1'!AW58*'Data Training 1'!AW64*'Data Training 1'!AW69*'Data Training 1'!AW75*'Data Training 1'!AW81*'Data Training 1'!AW87*'Data Training 1'!AW92*'Data Training 1'!AW100*'Data Training 1'!AW106*'Data Training 1'!AW110*'Data Training 1'!AW116*'Data Training 1'!AW124*'Data Training 1'!AW130*'Data Training 1'!AW136*'Data Training 1'!AW141*'Data Training 1'!AW145*'Data Training 1'!AW151*'Data Training 1'!AW159*'Data Training 1'!AW163*'Data Training 1'!AW167*'Data Training 1'!AW171*'Data Training 1'!AW175*'Data Training 1'!AW179*'Data Training 1'!AW183*'Data Training 1'!AW187*'Data Training 1'!AW192*'Data Training 1'!AW195*'Data Training 1'!AW200*'Data Training 1'!AW203*'Data Training 1'!AW207*'Data Training 1'!AW211*'Data Training 1'!AW216 -> 0
A8: =ROW()-1 -> 7 | B8: Ahmad Munir | C8: 2 | D8: D | E8: B | F8: A | G8: B | H8: D | I8: D | J8: B | K8: A | L8: B | M8: B | N8: A | O8: A | P8: D | Q8: B | R8: A | S8: D | T8: D | U8: D | V8: B | W8: A | X8: A | Y8: A | Z8: B | AA8: A | AB8: A | AC8: A | AD8: A | AE8: A | AF8: A | AG8: B | AH8: A | AI8: B | AJ8: A | AK8: A | AL8: A | AM8: B | AO8: P(Kesejahteraan|5) = | AQ8: ='Data Training 1'!AW26*'Data Training 1'!AX31*'Data Training 1'!AX40*'Data Training 1'!AX44*'Data Training 1'!AX52*'Data Training 1'!AX58*'Data Training 1'!AX64*'Data Training 1'!AX69*'Data Training 1'!AX75*'Data Training 1'!AX81*'Data Training 1'!AX87*'Data Training 1'!AX92*'Data Training 1'!AX100*'Data Training 1'!AX106*'Data Training 1'!AX110*'Data Training 1'!AX116*'Data Training 1'!AX124*'Data Training 1'!AX130*'Data Training 1'!AX136*'Data Training 1'!AX141*'Data Training 1'!AX145*'Data Training 1'!AX151*'Data Training 1'!AX159*'Data Training 1'!AX163*'Data Training 1'!AX167*'Data Training 1'!AX171*'Data Training 1'!AX175*'Data Training 1'!AX179*'Data Training 1'!AX183*'Data Training 1'!AX187*'Data Training 1'!AX192*'Data Training 1'!AX195*'Data Training 1'!AX200*'Data Training 1'!AX203*'Data Training 1'!AX207*'Data Training 1'!AX211*'Data Training 1'!AX216 -> 0
A9: =ROW()-1 -> 8 | B9: Yudi Irawan | C9: 2 | D9: D | E9: D | F9: B | G9: D | H9: D | I9: D | J9: C | K9: C | L9: B | M9: C | N9: C | O9: B | P9: D | Q9: B | R9: A | S9: D | T9: D | U9: D | V9: D | W9: A | X9: B | Y9: C | Z9: B | AA9: A | AB9: A | AC9: A | AD9: A | AE9: A | AF9: A | AG9: B | AH9: A | AI9: A | AJ9: A | AK9: A | AL9: B | AM9: A | AO9: P(Kesejahteraan|6) = | AQ9: ='Data Training 1'!AW27*'Data Training 1'!AY31*'Data Training 1'!AY40*'Data Training 1'!AY44*'Data Training 1'!AY52*'Data Training 1'!AY58*'Data Training 1'!AY64*'Data Training 1'!AY69*'Data Training 1'!AY75*'Data Training 1'!AY81*'Data Training 1'!AY87*'Data Training 1'!AY92*'Data Training 1'!AY100*'Data Training 1'!AY106*'Data Training 1'!AY110*'Data Training 1'!AY116*'Data Training 1'!AY124*'Data Training 1'!AY130*'Data Training 1'!AY136*'Data Training 1'!AY141*'Data Training 1'!AY145*'Data Training 1'!AY151*'Data Training 1'!AY159*'Data Training 1'!AY163*'Data Training 1'!AY167*'Data Training 1'!AY171*'Data Training 1'!AY175*'Data Training 1'!AY179*'Data Training 1'!AY183*'Data Training 1'!AY187*'Data Training 1'!AY192*'Data Training 1'!AY195*'Data Training 1'!AY200*'Data Training 1'!AY203*'Data Training 1'!AY207*'Data Training 1'!AY211*'Data Training 1'!AY216 -> 0
A10: =ROW()-1 -> 9 | B10: Bambang Rudianto | C10: 2 | D10: A | E10: D | F10: B | G10: D | H10: D | I10: D | J10: D | K10: C | L10: B | M10: C | N10: B | O10: C | P10: D | Q10: B | R10: B | S10: D | T10: D | U10: D | V10: A | W10: A | X10: B | Y10: C | Z10: B | AA10: A | AB10: A | AC10: A | AD10: A | AE10: A | AF10: A | AG10: B | AH10: A | AI10: A | AJ10: A | AK10: A | AL10: A | AM10: B | AO10: Hasil prediksi | AQ10: Kelas kesejahteraan 1 | AR10: sesuai dengan data aktual
A11: =ROW()-1 -> 10 | B11: Suwarno | C11: 2 | D11: C | E11: B | F11: C | G11: D | H11: D | I11: D | J11: D | K11: C | L11: B | M11: B | N11: C | O11: D | P11: D | Q11: B | R11: C | S11: D | T11: D | U11: D | V11: D | W11: A | X11: A | Y11: A | Z11: B | AA11: A | AB11: A | AC11: A | AD11: A | AE11: A | AF11: A | AG11: B | AH11: A | AI11: B | AJ11: A | AK11: A | AL11: A | AM11: B
A12: =ROW()-1 -> 11 | B12: Sandik | C12: 2 | D12: A | E12: D | F12: D | G12: D | H12: D | I12: D | J12: D | K12: C | L12: B | M12: A | N12: A | O12: C | P12: D | Q12: A | R12: C | S12: D | T12: C | U12: D | V12: D | W12: C | X12: A | Y12: A | Z12: B | AA12: A | AB12: A | AC12: A | AD12: A | AE12: A | AF12: A | AG12: A | AH12: A | AI12: A | AJ12: A | AK12: A | AL12: A | AM12: B | AN12: 2 | AO12: Juariyah | AQ12: Kelas Kesejahteraan | AR12: IM 1 | AS12: IM 2 | AT12: IM 3 | AU12: IM 4 | AV12: IM 5 | AW12: IM 6 | AX12: IM 7 | AY12: IM 8 | AZ12: IM 9 | BA12: IM 10 | BB12: IM 11 | BC12: IM 12 | BD12: IM 13 | BE12: IM 14 | BF12: IM 15 | BG12: IM 16 | BH12: IM 17 | BI12: IM 18 | BJ12: IM 19 | BK12: IM 20 | BL12: IM 21 | BM12: IM 22 | BN12: IM 23 | BO12: IM 24 | BP12: IM 25 | BQ12: IM 26 | BR12: IM 27 | BS12: IM 28 | BT12: IM 29 | BU12: IM 30 | BV12: IM 31 | BW12: IM 32 | BX12: IM 33 | BY12: IM 34 | BZ12: IM 35 | CA12: IM 36
A13: =ROW()-1 -> 12 | B13: Trio Suparman | C13: 2 | D13: A | E13: D | F13: B | G13: C | H13: D | I13: D | J13: D | K13: C | L13: C | M13: B | N13: A | O13: C | P13: D | Q13: B | R13: A | S13: D | T13: D | U13: D | V13: A | W13: A | X13: B | Y13: A | Z13: B | AA13: A | AB13: A | AC13: A | AD13: A | AE13: A | AF13: A | AG13: B | AH13: A | AI13: B | AJ13: A | AK13: A | AL13: A | AM13: A | AQ13: 1 | AR13: C | AS13: B | AT13: A | AU13: D | AV13: D | AW13: D | AX13: D | AY13: C | AZ13: B | BA13: B | BB13: A | BC13: B | BD13: D | BE13: B | BF13: B | BG13: D | BH13: D | BI13: D | BJ13: C | BK13: A | BL13: B | BM13: C | BN13: B | BO13: A | BP13: A | BQ13: A | BR13: A | BS13: A | BT13: A | BU13: A | BV13: A | BW13: A | BX13: A | BY13: A | BZ13: B | CA13: B
A14: =ROW()-1 -> 13 | B14: Sugeng | C14: 3 | D14: C | E14: B | F14: B | G14: C | H14: D | I14: D | J14: D | K14: C | L14: B | M14: B | N14: B | O14: C | P14: D | Q14: B | R14: B | S14: D | T14: D | U14: D | V14: D | W14: A | X14: B | Y14: C | Z14: B | AA14: A | AB14: A | AC14: A | AD14: A | AE14: A | AF14: A | AG14: B | AH14: A | AI14: B | AJ14: A | AK14: A | AL14: B | AM14: B | AO14: P(Kesejahteraan|1) = | AQ14: ='Data Training 1'!AW22*'Data Training 1'!AT33*'Data Training 1'!AT38*'Data Training 1'!AT43*'Data Training 1'!AT52*'Data Training 1'!AT58*'Data Training 1'!AT64*'Data Training 1'!AT70*'Data Training 1'!AT75*'Data Training 1'!AT80*'Data Training 1'!AT86*'Data Training 1'!AT91*'Data Training 1'!AT98*'Data Training 1'!AT106*'Data Training 1'!AT110*'Data Training 1'!AT116*'Data Training 1'!AT124*'Data Training 1'!AT130*'Data Training 1'!AT136*'Data Training 1'!AT141*'Data Training 1'!AT145*'Data Training 1'!AT152*'Data Training 1'!AT159*'Data Training 1'!AT164*'Data Training 1'!AT167*'Data Training 1'!AT171*'Data Training 1'!AT175*'Data Training 1'!AT179*'Data Training 1'!AT183*'Data Training 1'!AT187*'Data Training 1'!AT191*'Data Training 1'!AT195*'Data Training 1'!AT199*'Data Training 1'!AT203*'Data Training 1'!AT207*'Data Training 1'!AT212*'Data Training 1'!AT216 -> 4.0019048e-09
A15: =ROW()-1 -> 14 | B15: Nova Putra | C15: 3 | D15: C | E15: B | F15: B | G15: C | H15: D | I15: C | J15: D | K15: C | L15: B | M15: A | N15: A | O15: D | P15: D | Q15: A | R15: D | S15: D | T15: D | U15: D | V15: D | W15: A | X15: B | Y15: A | Z15: A | AA15: A | AB15: A | AC15: A | AD15: A | AE15: A | AF15: A | AG15: A | AH15: A | AI15: B | AJ15: A | AK15: A | AL15: B | AM15: A | AO15: P(Kesejahteraan|2) = | AQ15: ='Data Training 1'!AW23*'Data Training 1'!AU33*'Data Training 1'!AU38*'Data Training 1'!AU43*'Data Training 1'!AU52*'Data Training 1'!AU58*'Data Training 1'!AU64*'Data Training 1'!AU70*'Data Training 1'!AU75*'Data Training 1'!AU80*'Data Training 1'!AU86*'Data Training 1'!AU91*'Data Training 1'!AU98*'Data Training 1'!AU106*'Data Training 1'!AU110*'Data Training 1'!AU116*'Data Training 1'!AU124*'Data Training 1'!AU130*'Data Training 1'!AU136*'Data Training 1'!AU141*'Data Training 1'!AU145*'Data Training 1'!AU152*'Data Training 1'!AU159*'Data Training 1'!AU164*'Data Training 1'!AU167*'Data Training 1'!AU171*'Data Training 1'!AU175*'Data Training 1'!AU179*'Data Training 1'!AU183*'Data Training 1'!AU187*'Data Training 1'!AU191*'Data Training 1'!AU195*'Data Training 1'!AU199*'Data Training 1'!AU203*'Data Training 1'!AU207*'Data Training 1'!AU212*'Data Training 1'!AU216 -> 5.1357778e-12
A16: =ROW()-1 -> 15 | B16: Galih Sujitno | C16: 3 | D16: C | E16: B | F16: B | G16: D | H16: D | I16: D | J16: C | K16: C | L16: B | M16: B | N16: A | O16: D | P16: C | Q16: B | R16: C | S16: D | T16: D | U16: D | V16: D | W16: A | X16: B | Y16: B | Z16: B | AA16: A | AB16: A | AC16: A | AD16: A | AE16: A | AF16: A | AG16: B | AH16: A | AI16: B | AJ16: A | AK16: A | AL16: B | AM16: B | AO16: P(Kesejahteraan|3) = | AQ16: ='Data Training 1'!AW24*'Data Training 1'!AV33*'Data Training 1'!AV38*'Data Training 1'!AV43*'Data Training 1'!AV52*'Data Training 1'!AV58*'Data Training 1'!AV64*'Data Training 1'!AV70*'Data Training 1'!AV75*'Data Training 1'!AV80*'Data Training 1'!AV86*'Data Training 1'!AV91*'Data Training 1'!AV98*'Data Training 1'!AV106*'Data Training 1'!AV110*'Data Training 1'!AV116*'Data Training 1'!AV124*'Data Training 1'!AV130*'Data Training 1'!AV136*'Data Training 1'!AV141*'Data Training 1'!AV145*'Data Training 1'!AV152*'Data Training 1'!AV159*'Data Training 1'!AV164*'Data Training 1'!AV167*'Data Training 1'!AV171*'Data Training 1'!AV175*'Data Training 1'!AV179*'Data Training 1'!AV183*'Data Training 1'!AV187*'Data Training 1'!AV191*'Data Training 1'!AV195*'Data Training 1'!AV199*'Data Training 1'!AV203*'Data Training 1'!AV207*'Data Training 1'!AV212*'Data Training 1'!AV216 -> 0
A17: =ROW()-1 -> 16 | B17: Achmad Sholik | C17: 3 | D17: C | E17: D | F17: B | G17: B | H17: D | I17: D | J17: C | K17: C | L17: B | M17: A | N17: A | O17: D | P17: B | Q17: B | R17: C | S17: D | T17: B | U17: C | V17: D | W17: A | X17: B | Y17: C | Z17: B | AA17: A | AB17: A | AC17: A | AD17: A | AE17: A | AF17: A | AG17: B | AH17: A | AI17: B | AJ17: A | AK17: A | AL17: A | AM17: B | AO17: P(Kesejahteraan|4) = | AQ17: ='Data Training 1'!AW25*'Data Training 1'!AW33*'Data Training 1'!AW38*'Data Training 1'!AW43*'Data Training 1'!AW52*'Data Training 1'!AW58*'Data Training 1'!AW64*'Data Training 1'!AW70*'Data Training 1'!AW75*'Data Training 1'!AW80*'Data Training 1'!AW86*'Data Training 1'!AW91*'Data Training 1'!AW98*'Data Training 1'!AW106*'Data Training 1'!AW110*'Data Training 1'!AW116*'Data Training 1'!AW124*'Data Training 1'!AW130*'Data Training 1'!AW136*'Data Training 1'!AW141*'Data Training 1'!AW145*'Data Training 1'!AW152*'Data Training 1'!AW159*'Data Training 1'!AW164*'Data Training 1'!AW167*'Data Training 1'!AW171*'Data Training 1'!AW175*'Data Training 1'!AW179*'Data Training 1'!AW183*'Data Training 1'!AW187*'Data Training 1'!AW191*'Data Training 1'!AW195*'Data Training 1'!AW199*'Data Training 1'!AW203*'Data Training 1'!AW207*'Data Training 1'!AW212*'Data Training 1'!AW216 -> 0
A18: =ROW()-1 -> 17 | B18: Suliani | C18: 3 | D18: A | E18: B | F18: D | G18: D | H18: D | I18: D | J18: D | K18: C | L18: B | M18: B | N18: C | O18: C | P18: D | Q18: B | R18: C | S18: C | T18: D | U18: D | V18: D | W18: B | X18: D | Y18: D | Z18: A | AA18: A | AB18: A | AC18: A | AD18: A | AE18: A | AF18: A | AG18: B | AH18: A | AI18: B | AJ18: A | AK18: A | AL18: B | AM18: B | AO18: P(Kesejahteraan|5) = | AQ18: ='Data Training 1'!AW26*'Data Training 1'!AX33*'Data Training 1'!AX38*'Data Training 1'!AX43*'Data Training 1'!AX52*'Data Training 1'!AX58*'Data Training 1'!AX64*'Data Training 1'!AX70*'Data Training 1'!AX75*'Data Training 1'!AX80*'Data Training 1'!AX86*'Data Training 1'!AX91*'Data Training 1'!AX98*'Data Training 1'!AX106*'Data Training 1'!AX110*'Data Training 1'!AX116*'Data Training 1'!AX124*'Data Training 1'!AX130*'Data Training 1'!AX136*'Data Training 1'!AX141*'Data Training 1'!AX145*'Data Training 1'!AX152*'Data Training 1'!AX159*'Data Training 1'!AX164*'Data Training 1'!AX167*'Data Training 1'!AX171*'Data Training 1'!AX175*'Data Training 1'!AX179*'Data Training 1'!AX183*'Data Training 1'!AX187*'Data Training 1'!AX191*'Data Training 1'!AX195*'Data Training 1'!AX199*'Data Training 1'!AX203*'Data Training 1'!AX207*'Data Training 1'!AX212*'Data Training 1'!AX216 -> 0
A19: =ROW()-1 -> 18 | B19: Suti | C19: 3 | D19: D | E19: A | F19: A | G19: D | H19: D | I19: D | J19: D | K19: C | L19: C | M19: B | N19: A | O19: C | P19: C | Q19: C | R19: D | S19: D | T19: B | U19: B | V19: C | W19: A | X19: D | Y19: B | Z19: B | AA19: B | AB19: B | AC19: A | AD19: A | AE19: A | AF19: A | AG19: B | AH19: A | AI19: A | AJ19: A | AK19: A | AL19: A | AM19: B | AO19: P(Kesejahteraan|6) = | AQ19: ='Data Training 1'!AW27*'Data Training 1'!AY33*'Data Training 1'!AY38*'Data Training 1'!AY43*'Data Training 1'!AY52*'Data Training 1'!AY58*'Data Training 1'!AY64*'Data Training 1'!AY70*'Data Training 1'!AY75*'Data Training 1'!AY80*'Data Training 1'!AY86*'Data Training 1'!AY91*'Data Training 1'!AY98*'Data Training 1'!AY106*'Data Training 1'!AY110*'Data Training 1'!AY116*'Data Training 1'!AY124*'Data Training 1'!AY130*'Data Training 1'!AY136*'Data Training 1'!AY141*'Data Training 1'!AY145*'Data Training 1'!AY152*'Data Training 1'!AY159*'Data Training 1'!AY164*'Data Training 1'!AY167*'Data Training 1'!AY171*'Data Training 1'!AY175*'Data Training 1'!AY179*'Data Training 1'!AY183*'Data Training 1'!AY187*'Data Training 1'!AY191*'Data Training 1'!AY195*'Data Training 1'!AY199*'Data Training 1'!AY203*'Data Training 1'!AY207*'Data Training 1'!AY212*'Data Training 1'!AY216 -> 0
A20: =ROW()-1 -> 19 | B20: Agustian Juari | C20: 4 | D20: B | E20: B | F20: B | G20: D | H20: D | I20: D | J20: D | K20: C | L20: C | M20: B | N20: A | O20: D | P20: D | Q20: B | R20: C | S20: D | T20: D | U20: D | V20: A | W20: A | X20: A | Y20: C | Z20: B | AA20: A | AB20: A | AC20: A | AD20: A | AE20: A | AF20: B | AG20: B | AH20: A | AI20: B | AJ20: B | AK20: A | AL20: A | AM20: B | AO20: Hasil prediksi | AQ20: Kelas kesejahteraan 2 | AR20: Tidak sesuai dengan data aktual
A21: =ROW()-1 -> 20 | B21: Tri Bagusanto | C21: 4 | D21: D | E21: D | F21: C | G21: D | H21: D | I21: D | J21: D | K21: C | L21: C | M21: C | N21: B | O21: D | P21: D | Q21: C | R21: C | S21: D | T21: D | U21: D | V21: D | W21: B | X21: B | Y21: C | Z21: B | AA21: A | AB21: A | AC21: A | AD21: A | AE21: A | AF21: B | AG21: B | AH21: A | AI21: B | AJ21: B | AK21: A | AL21: B | AM21: B
A22: =ROW()-1 -> 21 | B22: Muhammad Ali | C22: 4 | D22: D | E22: B | F22: C | G22: D | H22: D | I22: D | J22: C | K22: C | L22: B | M22: B | N22: B | O22: B | P22: C | Q22: C | R22: C | S22: D | T22: C | U22: C | V22: D | W22: B | X22: C | Y22: C | Z22: B | AA22: A | AB22: A | AC22: A | AD22: A | AE22: A | AF22: B | AG22: B | AH22: A | AI22: B | AJ22: A | AK22: A | AL22: A | AM22: B | AN22: 3 | AO22: Khoirun sasmito | AQ22: Kelas Kesejahteraan | AR22: IM 1 | AS22: IM 2 | AT22: IM 3 | AU22: IM 4 | AV22: IM 5 | AW22: IM 6 | AX22: IM 7 | AY22: IM 8 | AZ22: IM 9 | BA22: IM 10 | BB22: IM 11 | BC22: IM 12 | BD22: IM 13 | BE22: IM 14 | BF22: IM 15 | BG22: IM 16 | BH22: IM 17 | BI22: IM 18 | BJ22: IM 19 | BK22: IM 20 | BL22: IM 21 | BM22: IM 22 | BN22: IM 23 | BO22: IM 24 | BP22: IM 25 | BQ22: IM 26 | BR22: IM 27 | BS22: IM 28 | BT22: IM 29 | BU22: IM 30 | BV22: IM 31 | BW22: IM 32 | BX22: IM 33 | BY22: IM 34 | BZ22: IM 35 | CA22: IM 36
A23: =ROW()-1 -> 22 | B23: Suhadak | C23: 4 | D23: D | E23: D | F23: C | G23: D | H23: D | I23: D | J23: D | K23: C | L23: B | M23: A | N23: A | O23: B | P23: C | Q23: C | R23: B | S23: D | T23: B | U23: C | V23: D | W23: B | X23: A | Y23: A | Z23: B | AA23: A | AB23: A | AC23: A | AD23: A | AE23: A | AF23: A | AG23: B | AH23: B | AI23: B | AJ23: A | AK23: A | AL23: B | AM23: B | AQ23: 1 | AR23: C | AS23: D | AT23: B | AU23: D | AV23: D | AW23: B | AX23: C | AY23: C | AZ23: C | BA23: B | BB23: A | BC23: D | BD23: D | BE23: B | BF23: B | BG23: D | BH23: D | BI23: D | BJ23: D | BK23: A | BL23: B | BM23: C | BN23: B | BO23: A | BP23: A | BQ23: A | BR23: A | BS23: A | BT23: B | BU23: B | BV23: A | BW23: A | BX23: A | BY23: A | BZ23: A | CA23: B
A24: =ROW()-1 -> 23 | B24: Muchamad Basri | C24: 4 | D24: C | E24: D | F24: C | G24: D | H24: D | I24: D | J24: D | K24: C | L24: C | M24: C | N24: D | O24: A | P24: D | Q24: C | R24: A | S24: D | T24: D | U24: D | V24: A | W24: B | X24: A | Y24: A | Z24: B | AA24: A | AB24: A | AC24: A | AD24: A | AE24: A | AF24: A | AG24: B | AH24: A | AI24: B | AJ24: A | AK24: A | AL24: B | AM24: B | AO24: P(Kesejahteraan|1) = | AQ24: ='Data Training 1'!AW22*'Data Training 1'!AT33*'Data Training 1'!AT40*'Data Training 1'!AT44*'Data Training 1'!AT52*'Data Training 1'!AT58*'Data Training 1'!AT62*'Data Training 1'!AT69*'Data Training 1'!AT75*'Data Training 1'!AT81*'Data Training 1'!AT86*'Data Training 1'!AT91*'Data Training 1'!AT100*'Data Training 1'!AT106*'Data Training 1'!AT110*'Data Training 1'!AT116*'Data Training 1'!AT124*'Data Training 1'!AT130*'Data Training 1'!AT136*'Data Training 1'!AT142*'Data Training 1'!AT145*'Data Training 1'!AT152*'Data Training 1'!AT159*'Data Training 1'!AT164*'Data Training 1'!AT167*'Data Training 1'!AT171*'Data Training 1'!AT175*'Data Training 1'!AT179*'Data Training 1'!AT183*'Data Training 1'!AT188*'Data Training 1'!AT192*'Data Training 1'!AT195*'Data Training 1'!AT199*'Data Training 1'!AT203*'Data Training 1'!AT207*'Data Training 1'!AT211*'Data Training 1'!AT216 -> 2.2510714e-10
A25: =ROW()-1 -> 24 | B25: Erwin Suryawardhani | C25: 4 | D25: B | E25: D | F25: A | G25: D | H25: D | I25: D | J25: D | K25: C | L25: C | M25: A | N25: A | O25: D | P25: C | Q25: B | R25: D | S25: D | T25: C | U25: D | V25: D | W25: A | X25: A | Y25: C | Z25: B | AA25: A | AB25: A | AC25: A | AD25: A | AE25: A | AF25: A | AG25: B | AH25: A | AI25: B | AJ25: A | AK25: A | AL25: A | AM25: B | AO25: P(Kesejahteraan|2) = | AQ25: ='Data Training 1'!AW23*'Data Training 1'!AU33*'Data Training 1'!AU40*'Data Training 1'!AU44*'Data Training 1'!AU52*'Data Training 1'!AU58*'Data Training 1'!AU62*'Data Training 1'!AU69*'Data Training 1'!AU75*'Data Training 1'!AU81*'Data Training 1'!AU86*'Data Training 1'!AU91*'Data Training 1'!AU100*'Data Training 1'!AU106*'Data Training 1'!AU110*'Data Training 1'!AU116*'Data Training 1'!AU124*'Data Training 1'!AU130*'Data Training 1'!AU136*'Data Training 1'!AU142*'Data Training 1'!AU145*'Data Training 1'!AU152*'Data Training 1'!AU159*'Data Training 1'!AU164*'Data Training 1'!AU167*'Data Training 1'!AU171*'Data Training 1'!AU175*'Data Training 1'!AU179*'Data Training 1'!AU183*'Data Training 1'!AU188*'Data Training 1'!AU192*'Data Training 1'!AU195*'Data Training 1'!AU199*'Data Training 1'!AU203*'Data Training 1'!AU207*'Data Training 1'!AU211*'Data Training 1'!AU216 -> 0
A26: =ROW()-1 -> 25 | B26: Muhammad Tegar | C26: 5 | D26: D | E26: B | F26: B | G26: D | H26: D | I26: D | J26: D | K26: C | L26: C | M26: D | N26: B | O26: C | P26: D | Q26: C | R26: B | S26: D | T26: D | U26: D | V26: D | W26: B | X26: A | Y26: C | Z26: B | AA26: A | AB26: A | AC26: A | AD26: A | AE26: A | AF26: A | AG26: B | AH26: A | AI26: B | AJ26: A | AK26: A | AL26: A | AM26: B | AO26: P(Kesejahteraan|3) = | AQ26: ='Data Training 1'!AW24*'Data Training 1'!AV33*'Data Training 1'!AV40*'Data Training 1'!AV44*'Data Training 1'!AV52*'Data Training 1'!AV58*'Data Training 1'!AV62*'Data Training 1'!AV69*'Data Training 1'!AV75*'Data Training 1'!AV81*'Data Training 1'!AV86*'Data Training 1'!AV91*'Data Training 1'!AV100*'Data Training 1'!AV106*'Data Training 1'!AV110*'Data Training 1'!AV116*'Data Training 1'!AV124*'Data Training 1'!AV130*'Data Training 1'!AV136*'Data Training 1'!AV142*'Data Training 1'!AV145*'Data Training 1'!AV152*'Data Training 1'!AV159*'Data Training 1'!AV164*'Data Training 1'!AV167*'Data Training 1'!AV171*'Data Training 1'!AV175*'Data Training 1'!AV179*'Data Training 1'!AV183*'Data Training 1'!AV188*'Data Training 1'!AV192*'Data Training 1'!AV195*'Data Training 1'!AV199*'Data Training 1'!AV203*'Data Training 1'!AV207*'Data Training 1'!AV211*'Data Training 1'!AV216 -> 0
A27: =ROW()-1 -> 26 | B27: Suhadi Jayadi | C27: 5 | D27: D | E27: B | F27: D | G27: D | H27: D | I27: D | J27: D | K27: C | L27: C | M27: A | N27: A | O27: B | P27: D | Q27: C | R27: D | S27: C | T27: C | U27: D | V27: A | W27: B | X27: B | Y27: A | Z27: B | AA27: A | AB27: A | AC27: A | AD27: A | AE27: A | AF27: B | AG27: B | AH27: A | AI27: B | AJ27: A | AK27: A | AL27: A | AM27: B | AO27: P(Kesejahteraan|4) = | AQ27: ='Data Training 1'!AW25*'Data Training 1'!AW33*'Data Training 1'!AW40*'Data Training 1'!AW44*'Data Training 1'!AW52*'Data Training 1'!AW58*'Data Training 1'!AW62*'Data Training 1'!AW69*'Data Training 1'!AW75*'Data Training 1'!AW81*'Data Training 1'!AW86*'Data Training 1'!AW91*'Data Training 1'!AW100*'Data Training 1'!AW106*'Data Training 1'!AW110*'Data Training 1'!AW116*'Data Training 1'!AW124*'Data Training 1'!AW130*'Data Training 1'!AW136*'Data Training 1'!AW142*'Data Training 1'!AW145*'Data Training 1'!AW152*'Data Training 1'!AW159*'Data Training 1'!AW164*'Data Training 1'!AW167*'Data Training 1'!AW171*'Data Training 1'!AW175*'Data Training 1'!AW179*'Data Training 1'!AW183*'Data Training 1'!AW188*'Data Training 1'!AW192*'Data Training 1'!AW195*'Data Training 1'!AW199*'Data Training 1'!AW203*'Data Training 1'!AW207*'Data Training 1'!AW211*'Data Training 1'!AW216 -> 0
A28: =ROW()-1 -> 27 | B28: Sarman | C28: 5 | D28: D | E28: D | F28: C | G28: D | H28: D | I28: B | J28: D | K28: C | L28: C | M28: C | N28: C | O28: C | P28: C | Q28: B | R28: B | S28: D | T28: D | U28: D | V28: D | W28: B | X28: B | Y28: C | Z28: B | AA28: A | AB28: A | AC28: A | AD28: A | AE28: A | AF28: B | AG28: B | AH28: A | AI28: B | AJ28: B | AK28: A | AL28: B | AM28: B | AO28: P(Kesejahteraan|5) = | AQ28: ='Data Training 1'!AW26*'Data Training 1'!AX33*'Data Training 1'!AX40*'Data Training 1'!AX44*'Data Training 1'!AX52*'Data Training 1'!AX58*'Data Training 1'!AX62*'Data Training 1'!AX69*'Data Training 1'!AX75*'Data Training 1'!AX81*'Data Training 1'!AX86*'Data Training 1'!AX91*'Data Training 1'!AX100*'Data Training 1'!AX106*'Data Training 1'!AX110*'Data Training 1'!AX116*'Data Training 1'!AX124*'Data Training 1'!AX130*'Data Training 1'!AX136*'Data Training 1'!AX142*'Data Training 1'!AX145*'Data Training 1'!AX152*'Data Training 1'!AX159*'Data Training 1'!AX164*'Data Training 1'!AX167*'Data Training 1'!AX171*'Data Training 1'!AX175*'Data Training 1'!AX179*'Data Training 1'!AX183*'Data Training 1'!AX188*'Data Training 1'!AX192*'Data Training 1'!AX195*'Data Training 1'!AX199*'Data Training 1'!AX203*'Data Training 1'!AX207*'Data Training 1'!AX211*'Data Training 1'!AX216 -> 0
A29: =ROW()-1 -> 28 | B29: Fitri Ayu | C29: 5 | D29: C | E29: B | F29: D | G29: D | H29: D | I29: D | J29: D | K29: C | L29: B | M29: B | N29: D | O29: C | P29: D | Q29: C | R29: C | S29: D | T29: D | U29: D | V29: B | W29: B | X29: A | Y29: C | Z29: B | AA29: A | AB29: A | AC29: A | AD29: A | AE29: A | AF29: B | AG29: B | AH29: A | AI29: B | AJ29: A | AK29: A | AL29: A | AM29: B | AO29: P(Kesejahteraan|6) = | AQ29: ='Data Training 1'!AW27*'Data Training 1'!AY33*'Data Training 1'!AY40*'Data Training 1'!AY44*'Data Training 1'!AY52*'Data Training 1'!AY58*'Data Training 1'!AY62*'Data Training 1'!AY69*'Data Training 1'!AY75*'Data Training 1'!AY81*'Data Training 1'!AY86*'Data Training 1'!AY91*'Data Training 1'!AY100*'Data Training 1'!AY106*'Data Training 1'!AY110*'Data Training 1'!AY116*'Data Training 1'!AY124*'Data Training 1'!AY130*'Data Training 1'!AY136*'Data Training 1'!AY142*'Data Training 1'!AY145*'Data Training 1'!AY152*'Data Training 1'!AY159*'Data Training 1'!AY164*'Data Training 1'!AY167*'Data Training 1'!AY171*'Data Training 1'!AY175*'Data Training 1'!AY179*'Data Training 1'!AY183*'Data Training 1'!AY188*'Data Training 1'!AY192*'Data Training 1'!AY195*'Data Training 1'!AY199*'Data Training 1'!AY203*'Data Training 1'!AY207*'Data Training 1'!AY211*'Data Training 1'!AY216 -> 0
A30: =ROW()-1 -> 29 | B30: Mujiana | C30: 5 | D30: C | E30: B | F30: A | G30: D | H30: D | I30: B | J30: D | K30: C | L30: B | M30: C | N30: C | O30: D | P30: D | Q30: C | R30: D | S30: D | T30: B | U30: D | V30: C | W30: A | X30: A | Y30: C | Z30: B | AA30: A | AB30: A | AC30: A | AD30: A | AE30: A | AF30: A | AG30: B | AH30: A | AI30: B | AJ30: A | AK30: A | AL30: B | AM30: B | AO30: Hasil prediksi | AQ30: Kelas kesejahteraan 1 | AR30: sesuai dengan data aktual
A31: =ROW()-1 -> 30 | B31: Mahendra | C31: 5 | D31: D | E31: D | F31: B | G31: D | H31: D | I31: D | J31: D | K31: C | L31: C | M31: D | N31: C | O31: C | P31: A | Q31: B | R31: C | S31: D | T31: D | U31: D | V31: B | W31: B | X31: B | Y31: A | Z31: B | AA31: A | AB31: A | AC31: A | AD31: A | AE31: A | AF31: B | AG31: B | AH31: A | AI31: B | AJ31: A | AK31: A | AL31: B | AM31: B
A32: =ROW()-1 -> 31 | B32: Tribhuwana Tunggadewa | C32: 6 | D32: D | E32: D | F32: B | G32: D | H32: D | I32: D | J32: D | K32: C | L32: C | M32: A | N32: A | O32: A | P32: D | Q32: A | R32: D | S32: D | T32: D | U32: D | V32: B | W32: D | X32: C | Y32: C | Z32: B | AA32: A | AB32: A | AC32: A | AD32: A | AE32: A | AF32: A | AG32: B | AH32: A | AI32: B | AJ32: B | AK32: A | AL32: B | AM32: B | AN32: 4 | AO32: Abd. Rochim | AQ32: Kelas Kesejahteraan | AR32: IM 1 | AS32: IM 2 | AT32: IM 3 | AU32: IM 4 | AV32: IM 5 | AW32: IM 6 | AX32: IM 7 | AY32: IM 8 | AZ32: IM 9 | BA32: IM 10 | BB32: IM 11 | BC32: IM 12 | BD32: IM 13 | BE32: IM 14 | BF32: IM 15 | BG32: IM 16 | BH32: IM 17 | BI32: IM 18 | BJ32: IM 19 | BK32: IM 20 | BL32: IM 21 | BM32: IM 22 | BN32: IM 23 | BO32: IM 24 | BP32: IM 25 | BQ32: IM 26 | BR32: IM 27 | BS32: IM 28 | BT32: IM 29 | BU32: IM 30 | BV32: IM 31 | BW32: IM 32 | BX32: IM 33 | BY32: IM 34 | BZ32: IM 35 | CA32: IM 36
A33: =ROW()-1 -> 32 | B33: Pratama Putra | C33: 6 | D33: A | E33: D | F33: C | G33: D | H33: D | I33: D | J33: C | K33: C | L33: C | M33: A | N33: C | O33: D | P33: D | Q33: A | R33: D | S33: D | T33: D | U33: D | V33: D | W33: A | X33: B | Y33: C | Z33: B | AA33: A | AB33: A | AC33: A | AD33: B | AE33: A | AF33: B | AG33: B | AH33: B | AI33: B | AJ33: B | AK33: B | AL33: B | AM33: B | AQ33: 1 | AR33: D | AS33: B | AT33: C | AU33: B | AV33: D | AW33: D | AX33: D | AY33: C | AZ33: C | BA33: C | BB33: C | BC33: D | BD33: D | BE33: B | BF33: B | BG33: D | BH33: D | BI33: D | BJ33: D | BK33: A | BL33: A | BM33: A | BN33: B | BO33: B | BP33: B | BQ33: A | BR33: A | BS33: A | BT33: A | BU33: B | BV33: A | BW33: B | BX33: B | BY33: A | BZ33: A | CA33: B
A34: =ROW()-1 -> 33 | B34: Eka Rafi Abadi | C34: 6 | D34: D | E34: D | F34: B | G34: C | H34: D | I34: D | J34: D | K34: D | L34: C | M34: A | N34: A | O34: C | P34: D | Q34: C | R34: C | S34: D | T34: B | U34: D | V34: B | W34: C | X34: C | Y34: D | Z34: B | AA34: A | AB34: A | AC34: A | AD34: B | AE34: A | AF34: B | AG34: B | AH34: B | AI34: B | AJ34: B | AK34: B | AL34: B | AM34: B | AO34: P(Kesejahteraan|1) = | AQ34: ='Data Training 1'!AW22*'Data Training 1'!AT34*'Data Training 1'!AT38*'Data Training 1'!AT45*'Data Training 1'!AT50*'Data Training 1'!AT58*'Data Training 1'!AT64*'Data Training 1'!AT70*'Data Training 1'!AT75*'Data Training 1'!AT81*'Data Training 1'!AT87*'Data Training 1'!AT93*'Data Training 1'!AT100*'Data Training 1'!AT106*'Data Training 1'!AT110*'Data Training 1'!AT116*'Data Training 1'!AT124*'Data Training 1'!AT130*'Data Training 1'!AT136*'Data Training 1'!AT142*'Data Training 1'!AT145*'Data Training 1'!AT151*'Data Training 1'!AT157*'Data Training 1'!AT164*'Data Training 1'!AT168*'Data Training 1'!AT172*'Data Training 1'!AT175*'Data Training 1'!AT179*'Data Training 1'!AT183*'Data Training 1'!AT187*'Data Training 1'!AT192*'Data Training 1'!AT195*'Data Training 1'!AT200*'Data Training 1'!AT204*'Data Training 1'!AT207*'Data Training 1'!AT211*'Data Training 1'!AT216 -> 4.1700293e-11
